<?xml version="1.0" ?>
<robot name="rusty" xmlns:xacro="http://www.ros.org/wiki/xacro">

<xacro:include filename="$(find rusty_description)/urdf/materials.xacro" />
<xacro:include filename="$(find rusty_description)/urdf/rusty.trans" />
<xacro:include filename="$(find rusty_description)/urdf/rusty.gazebo" />
<link name="base_link">
  <inertial>
    <origin rpy="0 0 0" xyz="2.466462607454025e-05 -0.0003599108468317723 0.08582131513730787"/>
    <mass value="53.807172927927134"/>
    <inertia ixx="0.468173" ixy="-0.000374" ixz="-0.000189" iyy="1.127098" iyz="-0.000321" izz="1.39713"/>
  </inertial>
  <visual>
    <origin rpy="0 0 0" xyz="0 0 0"/>
    <geometry>
      <mesh filename="package://rusty_description/meshes/base_link.stl" scale="0.001 0.001 0.001"/>
    </geometry>
    <material name="silver"/>
  </visual>
  <collision>
    <origin rpy="0 0 0" xyz="0 0 0"/>
    <geometry>
      <mesh filename="package://rusty_description/meshes/base_link.stl" scale="0.001 0.001 0.001"/>
    </geometry>
  </collision>
</link>

<link name="LW2_1">
  <inertial>
    <origin rpy="0 0 0" xyz="6.522560269672795e-15 -0.0024993853022152457 -0.012999999999999998"/>
    <mass value="0.10446939585417521"/>
    <inertia ixx="4.3e-05" ixy="0.0" ixz="0.0" iyy="7.5e-05" iyz="0.0" izz="4.3e-05"/>
  </inertial>
  <visual>
    <origin rpy="0 0 0" xyz="0.15 -0.103475 -0.051"/>
    <geometry>
      <mesh filename="package://rusty_description/meshes/LW2_1.stl" scale="0.001 0.001 0.001"/>
    </geometry>
    <material name="silver"/>
  </visual>
  <collision>
    <origin rpy="0 0 0" xyz="0.15 -0.103475 -0.051"/>
    <geometry>
      <mesh filename="package://rusty_description/meshes/LW2_1.stl" scale="0.001 0.001 0.001"/>
    </geometry>
  </collision>
</link>

<link name="RW2_1">
  <inertial>
    <origin rpy="0 0 0" xyz="2.858824288409778e-15 -0.000500614697784868 -0.013000000000000005"/>
    <mass value="0.1044693958541752"/>
    <inertia ixx="4.3e-05" ixy="0.0" ixz="0.0" iyy="7.5e-05" iyz="0.0" izz="4.3e-05"/>
  </inertial>
  <visual>
    <origin rpy="0 0 0" xyz="0.15 0.103475 -0.051"/>
    <geometry>
      <mesh filename="package://rusty_description/meshes/RW2_1.stl" scale="0.001 0.001 0.001"/>
    </geometry>
    <material name="silver"/>
  </visual>
  <collision>
    <origin rpy="0 0 0" xyz="0.15 0.103475 -0.051"/>
    <geometry>
      <mesh filename="package://rusty_description/meshes/RW2_1.stl" scale="0.001 0.001 0.001"/>
    </geometry>
  </collision>
</link>

<link name="RW1_1">
  <inertial>
    <origin rpy="0 0 0" xyz="-3.552713678800501e-15 -0.0005006146977848264 -0.013000000000000005"/>
    <mass value="0.1044693958541752"/>
    <inertia ixx="4.3e-05" ixy="-0.0" ixz="0.0" iyy="7.5e-05" iyz="0.0" izz="4.3e-05"/>
  </inertial>
  <visual>
    <origin rpy="0 0 0" xyz="-0.15 0.103475 -0.051"/>
    <geometry>
      <mesh filename="package://rusty_description/meshes/RW1_1.stl" scale="0.001 0.001 0.001"/>
    </geometry>
    <material name="silver"/>
  </visual>
  <collision>
    <origin rpy="0 0 0" xyz="-0.15 0.103475 -0.051"/>
    <geometry>
      <mesh filename="package://rusty_description/meshes/RW1_1.stl" scale="0.001 0.001 0.001"/>
    </geometry>
  </collision>
</link>

<link name="LW1_1">
  <inertial>
    <origin rpy="0 0 0" xyz="-7.216449660063518e-15 -0.0004993853022152023 -0.012999999999999998"/>
    <mass value="0.10446939585417521"/>
    <inertia ixx="4.3e-05" ixy="-0.0" ixz="0.0" iyy="7.5e-05" iyz="0.0" izz="4.3e-05"/>
  </inertial>
  <visual>
    <origin rpy="0 0 0" xyz="-0.15 -0.103475 -0.051"/>
    <geometry>
      <mesh filename="package://rusty_description/meshes/LW1_1.stl" scale="0.001 0.001 0.001"/>
    </geometry>
    <material name="silver"/>
  </visual>
  <collision>
    <origin rpy="0 0 0" xyz="-0.15 -0.103475 -0.051"/>
    <geometry>
      <mesh filename="package://rusty_description/meshes/LW1_1.stl" scale="0.001 0.001 0.001"/>
    </geometry>
  </collision>
</link>

<link name="Lidar_1">
  <inertial>
    <origin rpy="0 0 0" xyz="0.0076200098286492435 7.987355384612333e-05 -0.008000000000000007"/>
    <mass value="0.008257286244679606"/>
    <inertia ixx="1e-06" ixy="-0.0" ixz="-0.0" iyy="0.0" iyz="0.0" izz="1e-06"/>
  </inertial>
  <visual>
    <origin rpy="0 0 0" xyz="-0.235 -0.0 -0.136"/>
    <geometry>
      <mesh filename="package://rusty_description/meshes/Lidar_1.stl" scale="0.001 0.001 0.001"/>
    </geometry>
    <material name="silver"/>
  </visual>
  <collision>
    <origin rpy="0 0 0" xyz="-0.235 -0.0 -0.136"/>
    <geometry>
      <mesh filename="package://rusty_description/meshes/Lidar_1.stl" scale="0.001 0.001 0.001"/>
    </geometry>
  </collision>
</link>

<joint name="LW2" type="continuous">
  <origin rpy="0 0 0" xyz="-0.15 0.103475 0.051"/>
  <parent link="base_link"/>
  <child link="LW2_1"/>
  <axis xyz="0.0 -1.0 0.0"/>
</joint>

<joint name="RW2 " type="continuous">
  <origin rpy="0 0 0" xyz="-0.15 -0.103475 0.051"/>
  <parent link="base_link"/>
  <child link="RW2_1"/>
  <axis xyz="0.0 -1.0 0.0"/>
</joint>

<joint name="RW1" type="continuous">
  <origin rpy="0 0 0" xyz="0.15 -0.103475 0.051"/>
  <parent link="base_link"/>
  <child link="RW1_1"/>
  <axis xyz="0.0 1.0 0.0"/>
</joint>

<joint name="LW1" type="continuous">
  <origin rpy="0 0 0" xyz="0.15 0.103475 0.051"/>
  <parent link="base_link"/>
  <child link="LW1_1"/>
  <axis xyz="0.0 1.0 0.0"/>
</joint>

<joint name="Lidar" type="fixed">
  <origin rpy="0 0 0" xyz="0.235 0.0 0.136"/>
  <parent link="base_link"/>
  <child link="Lidar_1"/>
</joint>

</robot>
